09/20/2020 12:51:37 AM - ERROR - Exception on / [GET]
Traceback (most recent call last):
  File "/home/kevin/.local/lib/python3.8/site-packages/flask/app.py", line 2447, in wsgi_app
    response = self.full_dispatch_request()
  File "/home/kevin/.local/lib/python3.8/site-packages/flask/app.py", line 1952, in full_dispatch_request
    rv = self.handle_user_exception(e)
  File "/home/kevin/.local/lib/python3.8/site-packages/flask/app.py", line 1821, in handle_user_exception
    reraise(exc_type, exc_value, tb)
  File "/home/kevin/.local/lib/python3.8/site-packages/flask/_compat.py", line 39, in reraise
    raise value
  File "/home/kevin/.local/lib/python3.8/site-packages/flask/app.py", line 1950, in full_dispatch_request
    rv = self.dispatch_request()
  File "/home/kevin/.local/lib/python3.8/site-packages/flask/app.py", line 1936, in dispatch_request
    return self.view_functions[rule.endpoint](**req.view_args)
  File "/mnt/c/Users/Kevin/Desktop/TTMapHistoryScraper/server.py", line 23, in hello_world
    return send_file("map_history.txt")
  File "/home/kevin/.local/lib/python3.8/site-packages/flask/helpers.py", line 629, in send_file
    file = open(filename, "rb")
FileNotFoundError: [Errno 2] No such file or directory: '/mnt/c/Users/Kevin/Desktop/TTMapHistoryScraper/map_history.txt'
09/20/2020 12:52:32 AM - ERROR - Exception on / [GET]
Traceback (most recent call last):
  File "/home/kevin/.local/lib/python3.8/site-packages/flask/app.py", line 2447, in wsgi_app
    response = self.full_dispatch_request()
  File "/home/kevin/.local/lib/python3.8/site-packages/flask/app.py", line 1952, in full_dispatch_request
    rv = self.handle_user_exception(e)
  File "/home/kevin/.local/lib/python3.8/site-packages/flask/app.py", line 1821, in handle_user_exception
    reraise(exc_type, exc_value, tb)
  File "/home/kevin/.local/lib/python3.8/site-packages/flask/_compat.py", line 39, in reraise
    raise value
  File "/home/kevin/.local/lib/python3.8/site-packages/flask/app.py", line 1950, in full_dispatch_request
    rv = self.dispatch_request()
  File "/home/kevin/.local/lib/python3.8/site-packages/flask/app.py", line 1936, in dispatch_request
    return self.view_functions[rule.endpoint](**req.view_args)
  File "/mnt/c/Users/Kevin/Desktop/TTMapHistoryScraper/server.py", line 23, in hello_world
    return send_file("map_history.txt")
  File "/home/kevin/.local/lib/python3.8/site-packages/flask/helpers.py", line 629, in send_file
    file = open(filename, "rb")
FileNotFoundError: [Errno 2] No such file or directory: '/mnt/c/Users/Kevin/Desktop/TTMapHistoryScraper/map_history.txt'
09/20/2020 12:52:35 AM - ERROR - Exception on / [GET]
Traceback (most recent call last):
  File "/home/kevin/.local/lib/python3.8/site-packages/flask/app.py", line 2447, in wsgi_app
    response = self.full_dispatch_request()
  File "/home/kevin/.local/lib/python3.8/site-packages/flask/app.py", line 1952, in full_dispatch_request
    rv = self.handle_user_exception(e)
  File "/home/kevin/.local/lib/python3.8/site-packages/flask/app.py", line 1821, in handle_user_exception
    reraise(exc_type, exc_value, tb)
  File "/home/kevin/.local/lib/python3.8/site-packages/flask/_compat.py", line 39, in reraise
    raise value
  File "/home/kevin/.local/lib/python3.8/site-packages/flask/app.py", line 1950, in full_dispatch_request
    rv = self.dispatch_request()
  File "/home/kevin/.local/lib/python3.8/site-packages/flask/app.py", line 1936, in dispatch_request
    return self.view_functions[rule.endpoint](**req.view_args)
  File "/mnt/c/Users/Kevin/Desktop/TTMapHistoryScraper/server.py", line 23, in hello_world
    return send_file("map_history.txt")
  File "/home/kevin/.local/lib/python3.8/site-packages/flask/helpers.py", line 629, in send_file
    file = open(filename, "rb")
FileNotFoundError: [Errno 2] No such file or directory: '/mnt/c/Users/Kevin/Desktop/TTMapHistoryScraper/map_history.txt'
09/20/2020 12:52:53 AM - ERROR - Exception on / [GET]
Traceback (most recent call last):
  File "/home/kevin/.local/lib/python3.8/site-packages/flask/app.py", line 2447, in wsgi_app
    response = self.full_dispatch_request()
  File "/home/kevin/.local/lib/python3.8/site-packages/flask/app.py", line 1952, in full_dispatch_request
    rv = self.handle_user_exception(e)
  File "/home/kevin/.local/lib/python3.8/site-packages/flask/app.py", line 1821, in handle_user_exception
    reraise(exc_type, exc_value, tb)
  File "/home/kevin/.local/lib/python3.8/site-packages/flask/_compat.py", line 39, in reraise
    raise value
  File "/home/kevin/.local/lib/python3.8/site-packages/flask/app.py", line 1950, in full_dispatch_request
    rv = self.dispatch_request()
  File "/home/kevin/.local/lib/python3.8/site-packages/flask/app.py", line 1936, in dispatch_request
    return self.view_functions[rule.endpoint](**req.view_args)
  File "/mnt/c/Users/Kevin/Desktop/TTMapHistoryScraper/server.py", line 23, in hello_world
    return send_file("map_history.txt")
  File "/home/kevin/.local/lib/python3.8/site-packages/flask/helpers.py", line 629, in send_file
    file = open(filename, "rb")
FileNotFoundError: [Errno 2] No such file or directory: '/mnt/c/Users/Kevin/Desktop/TTMapHistoryScraper/map_history.txt'
09/20/2020 12:52:56 AM - ERROR - Exception on / [GET]
Traceback (most recent call last):
  File "/home/kevin/.local/lib/python3.8/site-packages/flask/app.py", line 2447, in wsgi_app
    response = self.full_dispatch_request()
  File "/home/kevin/.local/lib/python3.8/site-packages/flask/app.py", line 1952, in full_dispatch_request
    rv = self.handle_user_exception(e)
  File "/home/kevin/.local/lib/python3.8/site-packages/flask/app.py", line 1821, in handle_user_exception
    reraise(exc_type, exc_value, tb)
  File "/home/kevin/.local/lib/python3.8/site-packages/flask/_compat.py", line 39, in reraise
    raise value
  File "/home/kevin/.local/lib/python3.8/site-packages/flask/app.py", line 1950, in full_dispatch_request
    rv = self.dispatch_request()
  File "/home/kevin/.local/lib/python3.8/site-packages/flask/app.py", line 1936, in dispatch_request
    return self.view_functions[rule.endpoint](**req.view_args)
  File "/mnt/c/Users/Kevin/Desktop/TTMapHistoryScraper/server.py", line 23, in hello_world
    return send_file("map_history.txt")
  File "/home/kevin/.local/lib/python3.8/site-packages/flask/helpers.py", line 629, in send_file
    file = open(filename, "rb")
FileNotFoundError: [Errno 2] No such file or directory: '/mnt/c/Users/Kevin/Desktop/TTMapHistoryScraper/map_history.txt'
09/20/2020 12:53:35 AM - INFO -  * Running on http://0.0.0.0:5000/ (Press CTRL+C to quit)
09/20/2020 12:53:45 AM - ERROR - Exception on / [GET]
Traceback (most recent call last):
  File "/home/kevin/.local/lib/python3.8/site-packages/flask/app.py", line 2447, in wsgi_app
    response = self.full_dispatch_request()
  File "/home/kevin/.local/lib/python3.8/site-packages/flask/app.py", line 1952, in full_dispatch_request
    rv = self.handle_user_exception(e)
  File "/home/kevin/.local/lib/python3.8/site-packages/flask/app.py", line 1821, in handle_user_exception
    reraise(exc_type, exc_value, tb)
  File "/home/kevin/.local/lib/python3.8/site-packages/flask/_compat.py", line 39, in reraise
    raise value
  File "/home/kevin/.local/lib/python3.8/site-packages/flask/app.py", line 1950, in full_dispatch_request
    rv = self.dispatch_request()
  File "/home/kevin/.local/lib/python3.8/site-packages/flask/app.py", line 1936, in dispatch_request
    return self.view_functions[rule.endpoint](**req.view_args)
  File "server.py", line 23, in hello_world
    return send_file("map_history.txt")
  File "/home/kevin/.local/lib/python3.8/site-packages/flask/helpers.py", line 629, in send_file
    file = open(filename, "rb")
FileNotFoundError: [Errno 2] No such file or directory: '/mnt/c/Users/Kevin/Desktop/TTMapHistoryScraper/map_history.txt'
09/20/2020 12:53:45 AM - INFO - 127.0.0.1 - - [20/Sep/2020 00:53:45] "[35m[1mGET / HTTP/1.1[0m" 500 -
09/20/2020 12:54:18 AM - ERROR - Exception on / [GET]
Traceback (most recent call last):
  File "/home/kevin/.local/lib/python3.8/site-packages/flask/app.py", line 2447, in wsgi_app
    response = self.full_dispatch_request()
  File "/home/kevin/.local/lib/python3.8/site-packages/flask/app.py", line 1952, in full_dispatch_request
    rv = self.handle_user_exception(e)
  File "/home/kevin/.local/lib/python3.8/site-packages/flask/app.py", line 1821, in handle_user_exception
    reraise(exc_type, exc_value, tb)
  File "/home/kevin/.local/lib/python3.8/site-packages/flask/_compat.py", line 39, in reraise
    raise value
  File "/home/kevin/.local/lib/python3.8/site-packages/flask/app.py", line 1950, in full_dispatch_request
    rv = self.dispatch_request()
  File "/home/kevin/.local/lib/python3.8/site-packages/flask/app.py", line 1936, in dispatch_request
    return self.view_functions[rule.endpoint](**req.view_args)
  File "/mnt/c/Users/Kevin/Desktop/TTMapHistoryScraper/server.py", line 23, in hello_world
    return send_file("map_history.txt")
  File "/home/kevin/.local/lib/python3.8/site-packages/flask/helpers.py", line 629, in send_file
    file = open(filename, "rb")
FileNotFoundError: [Errno 2] No such file or directory: '/mnt/c/Users/Kevin/Desktop/TTMapHistoryScraper/map_history.txt'
09/20/2020 12:55:52 AM - ERROR - Exception on / [GET]
Traceback (most recent call last):
  File "/home/kevin/.local/lib/python3.8/site-packages/flask/app.py", line 2447, in wsgi_app
    response = self.full_dispatch_request()
  File "/home/kevin/.local/lib/python3.8/site-packages/flask/app.py", line 1952, in full_dispatch_request
    rv = self.handle_user_exception(e)
  File "/home/kevin/.local/lib/python3.8/site-packages/flask/app.py", line 1821, in handle_user_exception
    reraise(exc_type, exc_value, tb)
  File "/home/kevin/.local/lib/python3.8/site-packages/flask/_compat.py", line 39, in reraise
    raise value
  File "/home/kevin/.local/lib/python3.8/site-packages/flask/app.py", line 1950, in full_dispatch_request
    rv = self.dispatch_request()
  File "/home/kevin/.local/lib/python3.8/site-packages/flask/app.py", line 1936, in dispatch_request
    return self.view_functions[rule.endpoint](**req.view_args)
  File "/mnt/c/Users/Kevin/Desktop/TTMapHistoryScraper/server.py", line 23, in hello_world
    return send_file("map_history.txt")
  File "/home/kevin/.local/lib/python3.8/site-packages/flask/helpers.py", line 629, in send_file
    file = open(filename, "rb")
FileNotFoundError: [Errno 2] No such file or directory: '/mnt/c/Users/Kevin/Desktop/TTMapHistoryScraper/map_history.txt'
09/20/2020 12:58:23 AM - INFO -  * Running on http://0.0.0.0:5000/ (Press CTRL+C to quit)
